Workbook

Sheet swiss_qna
A2: Staatssekretariat für Wirtschaft SECO
A3: Secrétariat d'Etat à l'économie SECO
A4: Segreteria di Stato dell’economia SECO
A5: Secretariat da stadi per l'economia SECO
A6: State Secretariat for Economic Affairs SECO
A8: You may choose the language to label the Swiss GDP and its production-side components in the dropdown-menu below.
A9: Pages labelled at the end with "_q" contain quarterly data, pages with "_y" contain yearly figures.
A10: Pages labelled at the beginning with "nom" contain figures at current prices, pages with "real" contain values at prices of the preceding year (chained values, reference year 2020), pages with "defl" contain implicit price deflators and those with "gc" contain contributions to real GDP-growth.
A12: Sie können im Dropdown-Menu die Sprache wählen, im welcher Sie das BIP der Schweiz gemäss Produktionsseite beschriftet haben möchten.
A13: Seiten mit der Endbezeichnung "_q" enthalten Quartalszahlen, diejenigen mit "_y" Jahreszahlen.
A14: Seiten mit der Anfangsbezeichnung "nom" enthalten Werte zu laufenden Preisen, diejenigen mit "real" Werte zu Preisen des Vorjahres (verkettet, Referenzjahr 2020), diejenigen mit "defl" implizite Deflatoren und diejenigen mit "gc" Beiträge zum realen BIP-Wachstum.
A16: Vous pouvez choisir ci-dessous la langue avec laquelle vous souhaitez visualiser le PIB de la Suisse selon l'approche par la production.
... A22: Le pagine contrassegnate all'inizio con "nom" contengono dati ai prezzi correnti, pagine con "real" contengono valori ai prezzi dell'anno precedente (serie concatenate, anno di riferimento 2020), pagine con "defl" contengono i deflatori impliciti, pagine con "gc" contengono i contributi alla crescita reale del PIL.

Sheet nom_q
A1: =INDIRECT("beschriftung!"&ADDRESS(beschriftung!$C$1*12+ROW(beschriftung!$A1)-1,COLUMN(beschriftung!A$1))) -> ESA 2010, Quarterly aggregates of Gross Domestic Product, production approach, raw data
A2: =INDIRECT("beschriftung!"&ADDRESS(beschriftung!$C$1*12+ROW(beschriftung!$A2)-1,COLUMN(beschriftung!A$1))) -> In Mio. Swiss Francs, at current prices, percentage change to previous year
C4: =INDIRECT("beschriftung!"&ADDRESS(beschriftung!$C$1*12+ROW(beschriftung!$A5)-1,COLUMN(beschriftung!C$1))) -> Gross domestic product | D4: =IF(INDIRECT("beschriftung.!"&ADDRESS(#REF!*12+ROW($A5)-1,COLUMN(D$1)))="","",INDIRECT("beschriftung.!"&ADDRESS(#REF!*12+ROW($A5)-1,COLUMN(D$1)))) -> #REF! | E4: =IF(INDIRECT("beschriftung.!"&ADDRESS(#REF!*12+ROW($A5)-1,COLUMN(E$1)))="","",INDIRECT("beschriftung.!"&ADDRESS(#REF!*12+ROW($A5)-1,COLUMN(E$1)))) -> #REF! | F4: =IF(INDIRECT("beschriftung.!"&ADDRESS(#REF!*12+ROW($A5)-1,COLUMN(F$1)))="","",INDIRECT("beschriftung.!"&ADDRESS(#REF!*12+ROW($A5)-1,COLUMN(F$1)))) -> #REF! | G4: =IF(INDIRECT("beschriftung.!"&ADDRESS(#REF!*12+ROW($A5)-1,COLUMN(G$1)))="","",INDIRECT("beschriftung.!"&ADDRESS(#REF!*12+ROW($A5)-1,COLUMN(G$1)))) -> #REF! | H4: =IF(INDIRECT("beschriftung.!"&ADDRESS(#REF!*12+ROW($A5)-1,COLUMN(H$1)))="","",INDIRECT("beschriftung.!"&ADDRESS(#REF!*12+ROW($A5)-1,COLUMN(H$1)))) -> #REF! | I4: =IF(INDIRECT("beschriftung.!"&ADDRESS(#REF!*12+ROW($A5)-1,COLUMN(I$1)))="","",INDIRECT("beschriftung.!"&ADDRESS(#REF!*12+ROW($A5)-1,COLUMN(I$1)))) -> #REF! | J4: =IF(INDIRECT("beschriftung.!"&ADDRESS(#REF!*12+ROW($A5)-1,COLUMN(J$1)))="","",INDIRECT("beschriftung.!"&ADDRESS(#REF!*12+ROW($A5)-1,COLUMN(J$1)))) -> #REF! | K4: =IF(INDIRECT("beschriftung.!"&ADDRESS(#REF!*12+ROW($A5)-1,COLUMN(K$1)))="","",INDIRECT("beschriftung.!"&ADDRESS(#REF!*12+ROW($A5)-1,COLUMN(K$1)))) -> #REF! | L4: =IF(INDIRECT("beschriftung.!"&ADDRESS(#REF!*12+ROW($A5)-1,COLUMN(L$1)))="","",INDIRECT("beschriftung.!"&ADDRESS(#REF!*12+ROW($A5)-1,COLUMN(L$1)))) -> #REF! | Q4: =IF(INDIRECT("beschriftung.!"&ADDRESS(#REF!*12+ROW($A5)-1,COLUMN(Q$1)))="","",INDIRECT("beschriftung.!"&ADDRESS(#REF!*12+ROW($A5)-1,COLUMN(Q$1)))) -> #REF! | R4: =IF(INDIRECT("beschriftung.!"&ADDRESS(#REF!*12+ROW($A5)-1,COLUMN(R$1)))="","",INDIRECT("beschriftung.!"&ADDRESS(#REF!*12+ROW($A5)-1,COLUMN(R$1)))) -> #REF! | U4: =IF(INDIRECT("beschriftung.!"&ADDRESS(#REF!*12+ROW($A5)-1,COLUMN(U$1)))="","",INDIRECT("beschriftung.!"&ADDRESS(#REF!*12+ROW($A5)-1,COLUMN(U$1)))) -> #REF! | V4: =IF(INDIRECT("beschriftung.!"&ADDRESS(#REF!*12+ROW($A5)-1,COLUMN(V$1)))="","",INDIRECT("beschriftung.!"&ADDRESS(#REF!*12+ROW($A5)-1,COLUMN(V$1)))) -> #REF! | W4: =IF(INDIRECT("beschriftung.!"&ADDRESS(#REF!*12+ROW($A5)-1,COLUMN(W$1)))="","",INDIRECT("beschriftung.!"&ADDRESS(#REF!*12+ROW($A5)-1,COLUMN(W$1)))) -> #REF! | X4: =IF(INDIRECT("beschriftung.!"&ADDRESS(#REF!*12+ROW($A5)-1,COLUMN(X$1)))="","",INDIRECT("beschriftung.!"&ADDRESS(#REF!*12+ROW($A5)-1,COLUMN(X$1)))) -> #REF! | AA4: =IF(INDIRECT("beschriftung.!"&ADDRESS(#REF!*12+ROW($A5)-1,COLUMN(AA$1)))="","",INDIRECT("beschriftung.!"&ADDRESS(#REF!*12+ROW($A5)-1,COLUMN(AA$1)))) -> #REF! | AB4: =IF(INDIRECT("beschriftung.!"&ADDRESS(#REF!*12+ROW($A5)-1,COLUMN(AB$1)))="","",INDIRECT("beschriftung.!"&ADDRESS(#REF!*12+ROW($A5)-1,COLUMN(AB$1)))) -> #REF! | AG4: =IF(INDIRECT("beschriftung.!"&ADDRESS(#REF!*12+ROW($A5)-1,COLUMN(AG$1)))="","",INDIRECT("beschriftung.!"&ADDRESS(#REF!*12+ROW($A5)-1,COLUMN(AG$1)))) -> #REF! | AH4: =IF(INDIRECT("beschriftung.!"&ADDRESS(#REF!*12+ROW($A5)-1,COLUMN(AH$1)))="","",INDIRECT("beschriftung.!"&ADDRESS(#REF!*12+ROW($A5)-1,COLUMN(AH$1)))) -> #REF! | AI4: =IF(INDIRECT("beschriftung.!"&ADDRESS(#REF!*12+ROW($A5)-1,COLUMN(AI$1)))="","",INDIRECT("beschriftung.!"&ADDRESS(#REF!*12+ROW($A5)-1,COLUMN(AI$1)))) -> #REF! | AJ4: =IF(INDIRECT("beschriftung.!"&ADDRESS(#REF!*12+ROW($A5)-1,COLUMN(AJ$1)))="","",INDIRECT("beschriftung.!"&ADDRESS(#REF!*12+ROW($A5)-1,COLUMN(AJ$1)))) -> #REF! | AM4: =IF(INDIRECT("beschriftung.!"&ADDRESS(#REF!*12+ROW($A5)-1,COLUMN(AM$1)))="","",INDIRECT("beschriftung.!"&ADDRESS(#REF!*12+ROW($A5)-1,COLUMN(AM$1)))) -> #REF! | AN4: =IF(INDIRECT("beschriftung.!"&ADDRESS(#REF!*12+ROW($A5)-1,COLUMN(AN$1)))="","",INDIRECT("beschriftung.!"&ADDRESS(#REF!*12+ROW($A5)-1,COLUMN(AN$1)))) -> #REF! | AO4: =IF(INDIRECT("beschriftung.!"&ADDRESS(#REF!*12+ROW($A5)-1,COLUMN(AO$1)))="","",INDIRECT("beschriftung.!"&ADDRESS(#REF!*12+ROW($A5)-1,COLUMN(AO$1)))) -> #REF! | AP4: =IF(INDIRECT("beschriftung.!"&ADDRESS(#REF!*12+ROW($A5)-1,COLUMN(AP$1)))="","",INDIRECT("beschriftung.!"&ADDRESS(#REF!*12+ROW($A5)-1,COLUMN(AP$1)))) -> #REF! | AQ4: =IF(INDIRECT("beschriftung.!"&ADDRESS(#REF!*12+ROW($A5)-1,COLUMN(AQ$1)))="","",INDIRECT("beschriftung.!"&ADDRESS(#REF!*12+ROW($A5)-1,COLUMN(AQ$1)))) -> #REF! | AR4: =IF(INDIRECT("beschriftung.!"&ADDRESS(#REF!*12+ROW($A5)-1,COLUMN(AR$1)))="","",INDIRECT("beschriftung.!"&ADDRESS(#REF!*12+ROW($A5)-1,COLUMN(AR$1)))) -> #REF! | AS4: =IF(INDIRECT("beschriftung.!"&ADDRESS(#REF!*12+ROW($A5)-1,COLUMN(AS$1)))="","",INDIRECT("beschriftung.!"&ADDRESS(#REF!*12+ROW($A5)-1,COLUMN(AS$1)))) -> #REF! | AT4: =IF(INDIRECT("beschriftung.!"&ADDRESS(#REF!*12+ROW($A5)-1,COLUMN(AT$1)))="","",INDIRECT("beschriftung.!"&ADDRESS(#REF!*12+ROW($A5)-1,COLUMN(AT$1)))) -> #REF! | ... AV4: =IF(INDIRECT("beschriftung.!"&ADDRESS(#REF!*12+ROW($A5)-1,COLUMN(AV$1)))="","",INDIRECT("beschriftung.!"&ADDRESS(#REF!*12+ROW($A5)-1,COLUMN(AV$1)))) -> #REF! | AY4: =IF(INDIRECT("beschriftung.!"&ADDRESS(#REF!*12+ROW($A5)-1,COLUMN(AY$1)))="","",INDIRECT("beschriftung.!"&ADDRESS(#REF!*12+ROW($A5)-1,COLUMN(AY$1)))) -> #REF! | AZ4: =IF(INDIRECT("beschriftung.!"&ADDRESS(#REF!*12+ROW($A5)-1,COLUMN(AZ$1)))="","",INDIRECT("beschriftung.!"&ADDRESS(#REF!*12+ROW($A5)-1,COLUMN(AZ$1)))) -> #REF! | BA4: =IF(INDIRECT("beschriftung.!"&ADDRESS(#REF!*12+ROW($A5)-1,COLUMN(BA$1)))="","",INDIRECT("beschriftung.!"&ADDRESS(#REF!*12+ROW($A5)-1,COLUMN(BA$1)))) -> #REF! | BB4: =IF(INDIRECT("beschriftung.!"&ADDRESS(#REF!*12+ROW($A5)-1,COLUMN(BB$1)))="","",INDIRECT("beschriftung.!"&ADDRESS(#REF!*12+ROW($A5)-1,COLUMN(BB$1)))) -> #REF! | BC4: =IF(INDIRECT("beschriftung.!"&ADDRESS(#REF!*12+ROW($A5)-1,COLUMN(BC$1)))="","",INDIRECT("beschriftung.!"&ADDRESS(#REF!*12+ROW($A5)-1,COLUMN(BC$1)))) -> #REF! | BD4: =IF(INDIRECT("beschriftung.!"&ADDRESS(#REF!*12+ROW($A5)-1,COLUMN(BD$1)))="","",INDIRECT("beschriftung.!"&ADDRESS(#REF!*12+ROW($A5)-1,COLUMN(BD$1)))) -> #REF! | BE4: =IF(INDIRECT("beschriftung.!"&ADDRESS(#REF!*12+ROW($A5)-1,COLUMN(BE$1)))="","",INDIRECT("beschriftung.!"&ADDRESS(#REF!*12+ROW($A5)-1,COLUMN(BE$1)))) -> #REF! | BF4: =IF(INDIRECT("beschriftung.!"&ADDRESS(#REF!*12+ROW($A5)-1,COLUMN(BF$1)))="","",INDIRECT("beschriftung.!"&ADDRESS(#REF!*12+ROW($A5)-1,COLUMN(BF$1)))) -> #REF!
E5: =INDIRECT("beschriftung!"&ADDRESS(beschriftung!$C$1*12+ROW(beschriftung!$A6)-1,COLUMN(beschriftung!D$1))) -> Gross value added before adjustments | F5: =IF(INDIRECT("beschriftung.!"&ADDRESS(#REF!*12+ROW($A6)-1,COLUMN(F$1)))="","",INDIRECT("beschriftung.!"&ADDRESS(#REF!*12+ROW($A6)-1,COLUMN(F$1)))) -> #REF! | G5: =IF(INDIRECT("beschriftung.!"&ADDRESS(#REF!*12+ROW($A6)-1,COLUMN(G$1)))="","",INDIRECT("beschriftung.!"&ADDRESS(#REF!*12+ROW($A6)-1,COLUMN(G$1)))) -> #REF! | H5: =IF(INDIRECT("beschriftung.!"&ADDRESS(#REF!*12+ROW($A6)-1,COLUMN(H$1)))="","",INDIRECT("beschriftung.!"&ADDRESS(#REF!*12+ROW($A6)-1,COLUMN(H$1)))) -> #REF! | I5: =IF(INDIRECT("beschriftung.!"&ADDRESS(#REF!*12+ROW($A6)-1,COLUMN(I$1)))="","",INDIRECT("beschriftung.!"&ADDRESS(#REF!*12+ROW($A6)-1,COLUMN(I$1)))) -> #REF! | J5: =IF(INDIRECT("beschriftung.!"&ADDRESS(#REF!*12+ROW($A6)-1,COLUMN(J$1)))="","",INDIRECT("beschriftung.!"&ADDRESS(#REF!*12+ROW($A6)-1,COLUMN(J$1)))) -> #REF! | K5: =IF(INDIRECT("beschriftung.!"&ADDRESS(#REF!*12+ROW($A6)-1,COLUMN(K$1)))="","",INDIRECT("beschriftung.!"&ADDRESS(#REF!*12+ROW($A6)-1,COLUMN(K$1)))) -> #REF! | L5: =IF(INDIRECT("beschriftung.!"&ADDRESS(#REF!*12+ROW($A6)-1,COLUMN(L$1)))="","",INDIRECT("beschriftung.!"&ADDRESS(#REF!*12+ROW($A6)-1,COLUMN(L$1)))) -> #REF! | Q5: =IF(INDIRECT("beschriftung.!"&ADDRESS(#REF!*12+ROW($A6)-1,COLUMN(Q$1)))="","",INDIRECT("beschriftung.!"&ADDRESS(#REF!*12+ROW($A6)-1,COLUMN(Q$1)))) -> #REF! | R5: =IF(INDIRECT("beschriftung.!"&ADDRESS(#REF!*12+ROW($A6)-1,COLUMN(R$1)))="","",INDIRECT("beschriftung.!"&ADDRESS(#REF!*12+ROW($A6)-1,COLUMN(R$1)))) -> #REF! | U5: =IF(INDIRECT("beschriftung.!"&ADDRESS(#REF!*12+ROW($A6)-1,COLUMN(U$1)))="","",INDIRECT("beschriftung.!"&ADDRESS(#REF!*12+ROW($A6)-1,COLUMN(U$1)))) -> #REF! | V5: =IF(INDIRECT("beschriftung.!"&ADDRESS(#REF!*12+ROW($A6)-1,COLUMN(V$1)))="","",INDIRECT("beschriftung.!"&ADDRESS(#REF!*12+ROW($A6)-1,COLUMN(V$1)))) -> #REF! | W5: =IF(INDIRECT("beschriftung.!"&ADDRESS(#REF!*12+ROW($A6)-1,COLUMN(W$1)))="","",INDIRECT("beschriftung.!"&ADDRESS(#REF!*12+ROW($A6)-1,COLUMN(W$1)))) -> #REF! | X5: =IF(INDIRECT("beschriftung.!"&ADDRESS(#REF!*12+ROW($A6)-1,COLUMN(X$1)))="","",INDIRECT("beschriftung.!"&ADDRESS(#REF!*12+ROW($A6)-1,COLUMN(X$1)))) -> #REF! | AA5: =IF(INDIRECT("beschriftung.!"&ADDRESS(#REF!*12+ROW($A6)-1,COLUMN(AA$1)))="","",INDIRECT("beschriftung.!"&ADDRESS(#REF!*12+ROW($A6)-1,COLUMN(AA$1)))) -> #REF! | AB5: =IF(INDIRECT("beschriftung.!"&ADDRESS(#REF!*12+ROW($A6)-1,COLUMN(AB$1)))="","",INDIRECT("beschriftung.!"&ADDRESS(#REF!*12+ROW($A6)-1,COLUMN(AB$1)))) -> #REF! | AG5: =IF(INDIRECT("beschriftung.!"&ADDRESS(#REF!*12+ROW($A6)-1,COLUMN(AG$1)))="","",INDIRECT("beschriftung.!"&ADDRESS(#REF!*12+ROW($A6)-1,COLUMN(AG$1)))) -> #REF! | AH5: =IF(INDIRECT("beschriftung.!"&ADDRESS(#REF!*12+ROW($A6)-1,COLUMN(AH$1)))="","",INDIRECT("beschriftung.!"&ADDRESS(#REF!*12+ROW($A6)-1,COLUMN(AH$1)))) -> #REF! | AI5: =IF(INDIRECT("beschriftung.!"&ADDRESS(#REF!*12+ROW($A6)-1,COLUMN(AI$1)))="","",INDIRECT("beschriftung.!"&ADDRESS(#REF!*12+ROW($A6)-1,COLUMN(AI$1)))) -> #REF! | AJ5: =IF(INDIRECT("beschriftung.!"&ADDRESS(#REF!*12+ROW($A6)-1,COLUMN(AJ$1)))="","",INDIRECT("beschriftung.!"&ADDRESS(#REF!*12+ROW($A6)-1,COLUMN(AJ$1)))) -> #REF! | AM5: =IF(INDIRECT("beschriftung.!"&ADDRESS(#REF!*12+ROW($A6)-1,COLUMN(AM$1)))="","",INDIRECT("beschriftung.!"&ADDRESS(#REF!*12+ROW($A6)-1,COLUMN(AM$1)))) -> #REF! | AN5: =IF(INDIRECT("beschriftung.!"&ADDRESS(#REF!*12+ROW($A6)-1,COLUMN(AN$1)))="","",INDIRECT("beschriftung.!"&ADDRESS(#REF!*12+ROW($A6)-1,COLUMN(AN$1)))) -> #REF! | AO5: =IF(INDIRECT("beschriftung.!"&ADDRESS(#REF!*12+ROW($A6)-1,COLUMN(AO$1)))="","",INDIRECT("beschriftung.!"&ADDRESS(#REF!*12+ROW($A6)-1,COLUMN(AO$1)))) -> #REF! | AP5: =IF(INDIRECT("beschriftung.!"&ADDRESS(#REF!*12+ROW($A6)-1,COLUMN(AP$1)))="","",INDIRECT("beschriftung.!"&ADDRESS(#REF!*12+ROW($A6)-1,COLUMN(AP$1)))) -> #REF! | AQ5: =IF(INDIRECT("beschriftung.!"&ADDRESS(#REF!*12+ROW($A6)-1,COLUMN(AQ$1)))="","",INDIRECT("beschriftung.!"&ADDRESS(#REF!*12+ROW($A6)-1,COLUMN(AQ$1)))) -> #REF! | AR5: =IF(INDIRECT("beschriftung.!"&ADDRESS(#REF!*12+ROW($A6)-1,COLUMN(AR$1)))="","",INDIRECT("beschriftung.!"&ADDRESS(#REF!*12+ROW($A6)-1,COLUMN(AR$1)))) -> #REF! | AS5: =IF(INDIRECT("beschriftung.!"&ADDRESS(#REF!*12+ROW($A6)-1,COLUMN(AS$1)))="","",INDIRECT("beschriftung.!"&ADDRESS(#REF!*12+ROW($A6)-1,COLUMN(AS$1)))) -> #REF! | AT5: =IF(INDIRECT("beschriftung.!"&ADDRESS(#REF!*12+ROW($A6)-1,COLUMN(AT$1)))="","",INDIRECT("beschriftung.!"&ADDRESS(#REF!*12+ROW($A6)-1,COLUMN(AT$1)))) -> #REF! | ... AV5: =IF(INDIRECT("beschriftung.!"&ADDRESS(#REF!*12+ROW($A6)-1,COLUMN(AV$1)))="","",INDIRECT("beschriftung.!"&ADDRESS(#REF!*12+ROW($A6)-1,COLUMN(AV$1)))) -> #REF! | AY5: =IF(INDIRECT("beschriftung.!"&ADDRESS(#REF!*12+ROW($A6)-1,COLUMN(AY$1)))="","",INDIRECT("beschriftung.!"&ADDRESS(#REF!*12+ROW($A6)-1,COLUMN(AY$1)))) -> #REF! | AZ5: =IF(INDIRECT("beschriftung.!"&ADDRESS(#REF!*12+ROW($A6)-1,COLUMN(AZ$1)))="","",INDIRECT("beschriftung.!"&ADDRESS(#REF!*12+ROW($A6)-1,COLUMN(AZ$1)))) -> #REF! | BA5: =INDIRECT("beschriftung!"&ADDRESS(beschriftung!$C$1*12+ROW(beschriftung!$A6)-1,COLUMN(beschriftung!AS$1))) -> Adjustments | BB5: =IF(INDIRECT("beschriftung.!"&ADDRESS(#REF!*12+ROW($A6)-1,COLUMN(BB$1)))="","",INDIRECT("beschriftung.!"&ADDRESS(#REF!*12+ROW($A6)-1,COLUMN(BB$1)))) -> #REF! | BC5: =IF(INDIRECT("beschriftung.!"&ADDRESS(#REF!*12+ROW($A6)-1,COLUMN(BC$1)))="","",INDIRECT("beschriftung.!"&ADDRESS(#REF!*12+ROW($A6)-1,COLUMN(BC$1)))) -> #REF! | BD5: =IF(INDIRECT("beschriftung.!"&ADDRESS(#REF!*12+ROW($A6)-1,COLUMN(BD$1)))="","",INDIRECT("beschriftung.!"&ADDRESS(#REF!*12+ROW($A6)-1,COLUMN(BD$1)))) -> #REF! | BE5: =IF(INDIRECT("beschriftung.!"&ADDRESS(#REF!*12+ROW($A6)-1,COLUMN(BE$1)))="","",INDIRECT("beschriftung.!"&ADDRESS(#REF!*12+ROW($A6)-1,COLUMN(BE$1)))) -> #REF! | BF5: =IF(INDIRECT("beschriftung.!"&ADDRESS(#REF!*12+ROW($A6)-1,COLUMN(BF$1)))="","",INDIRECT("beschriftung.!"&ADDRESS(#REF!*12+ROW($A6)-1,COLUMN(BF$1)))) -> #REF! | BG5: =IF(INDIRECT("beschriftung!"&ADDRESS(beschriftung!$C$1*12+ROW($A6)-1,COLUMN(BG$1)))="","",INDIRECT("beschriftung!"&ADDRESS(beschriftung!$C$1*12+ROW($A6)-1,COLUMN(BG$1)))) | BH5: =IF(INDIRECT("beschriftung!"&ADDRESS(beschriftung!$C$1*12+ROW($A6)-1,COLUMN(BH$1)))="","",INDIRECT("beschriftung!"&ADDRESS(beschriftung!$C$1*12+ROW($A6)-1,COLUMN(BH$1))))
G6: =INDIRECT("beschriftung!"&ADDRESS(beschriftung!$C$1*12+ROW(beschriftung!$A7)-1,COLUMN(beschriftung!E$1))) -> Agriculture, forestry and fishing | I6: =INDIRECT("beschriftung!"&ADDRESS(beschriftung!$C$1*12+ROW(beschriftung!$A7)-1,COLUMN(beschriftung!G$1))) -> Mining and quarrying | K6: =INDIRECT("beschriftung!"&ADDRESS(beschriftung!$C$1*12+ROW(beschriftung!$A7)-1,COLUMN(beschriftung!I$1))) -> Manufacturing | Q6: =INDIRECT("beschriftung!"&ADDRESS(beschriftung!$C$1*12+ROW(beschriftung!$A7)-1,COLUMN(beschriftung!M$1))) -> Electricity, gas, steam and air conditioning supply | S6: =INDIRECT("beschriftung!"&ADDRESS(beschriftung!$C$1*12+ROW(beschriftung!$A7)-1,COLUMN(beschriftung!O$1))) -> Water supply, sewerage, waste management and remediation activities | U6: =INDIRECT("beschriftung!"&ADDRESS(beschriftung!$C$1*12+ROW(beschriftung!$A7)-1,COLUMN(beschriftung!Q$1))) -> Construction | W6: =INDIRECT("beschriftung!"&ADDRESS(beschriftung!$C$1*12+ROW(beschriftung!$A7)-1,COLUMN(beschriftung!S$1))) -> Trade, repair of motor vehicles and motorcycles | AA6: =INDIRECT("beschriftung!"&ADDRESS(beschriftung!$C$1*12+ROW(beschriftung!$A7)-1,COLUMN(beschriftung!W$1))) -> Transportation and storage | AC6: =INDIRECT("beschriftung!"&ADDRESS(beschriftung!$C$1*12+ROW(beschriftung!$A7)-1,COLUMN(beschriftung!Y$1))) -> Accommodation and food service activities | AE6: =INDIRECT("beschriftung!"&ADDRESS(beschriftung!$C$1*12+ROW(beschriftung!$A7)-1,COLUMN(beschriftung!X$1))) -> Information and communication | AG6: =INDIRECT("beschriftung!"&ADDRESS(beschriftung!$C$1*12+ROW(beschriftung!$A7)-1,COLUMN(beschriftung!AA$1))) -> Financial and insurance activities | AM6: =INDIRECT("beschriftung!"&ADDRESS(beschriftung!$C$1*12+ROW(beschriftung!$A7)-1,COLUMN(beschriftung!AE$1))) -> Real estate, professional, scientific, technical activities and administrative services | AO6: =INDIRECT("beschriftung!"&ADDRESS(beschriftung!$C$1*12+ROW(beschriftung!$A7)-1,COLUMN(beschriftung!AG$1))) -> Public administration | AQ6: =INDIRECT("beschriftung!"&ADDRESS(beschriftung!$C$1*12+ROW(beschriftung!$A7)-1,COLUMN(beschriftung!AI$1))) -> Education | AS6: =INDIRECT("beschriftung!"&ADDRESS(beschriftung!$C$1*12+ROW(beschriftung!$A7)-1,COLUMN(beschriftung!AK$1))) -> Human health and social work activities | AU6: =INDIRECT("beschriftung!"&ADDRESS(beschriftung!$C$1*12+ROW(beschriftung!$A7)-1,COLUMN(beschriftung!AM$1))) -> Arts, entertainment and recreation | AW6: =INDIRECT("beschriftung!"&ADDRESS(beschriftung!$C$1*12+ROW(beschriftung!$A7)-1,COLUMN(beschriftung!AO$1))) -> Other service activities | AY6: =INDIRECT("beschriftung!"&ADDRESS(beschriftung!$C$1*12+ROW(beschriftung!$A7)-1,COLUMN(beschriftung!AQ$1))) -> Activities of housholds as employers and producers for own use | BC6: =INDIRECT("beschriftung!"&ADDRESS(beschriftung!$C$1*12+ROW(beschriftung!$A7)-1,COLUMN(beschriftung!AU$1))) -> Taxes on products | BE6: =INDIRECT("beschriftung!"&ADDRESS(beschriftung!$C$1*12+ROW(beschriftung!$A7)-1,COLUMN(beschriftung!AW$1))) -> Subsidies on products
M8: =INDIRECT("beschriftung!"&ADDRESS(beschriftung!$C$1*12+ROW(beschriftung!$A7),COLUMN(beschriftung!J$1))) -> thereof chemicals and pharmaceuticals | O8: =INDIRECT("beschriftung!"&ADDRESS(beschriftung!$C$1*12+ROW(beschriftung!$A7),COLUMN(beschriftung!K$1))) -> thereof other manufacturing | Y8: =INDIRECT("beschriftung!"&ADDRESS(beschriftung!$C$1*12+ROW(beschriftung!$A7),COLUMN(beschriftung!U$1))) -> thereof retail trade | AI8: =INDIRECT("beschriftung!"&ADDRESS(beschriftung!$C$1*12+ROW(beschriftung!$A7),COLUMN(beschriftung!AB$1))) -> thereof financial activities | AK8: =INDIRECT("beschriftung!"&ADDRESS(beschriftung!$C$1*12+ROW(beschriftung!$A7),COLUMN(beschriftung!AC$1))) -> thereof insurance activities
C11: B1GQ | E11: B1G | G11: NOGA 01-03 | I11: NOGA 05-09 | K11: NOGA 10-33 | M11: NOGA 19-21 | O11: NOGA 10-18; 22-33 | Q11: NOGA 35 | S11: NOGA 36-39 | U11: NOGA 41-43 | W11: NOGA 45-47 | Y11: NOGA 47 | AA11: NOGA 49-53 | AC11: NOGA 55-56 | AE11: NOGA 58-63 | AG11: NOGA 64-66 | AI11: NOGA 64 | AK11: NOGA 65 | AM11: NOGA 68-75; 77-82 | AO11: NOGA 84 | AQ11: NOGA 85 | AS11: NOGA 86-88 | AU11: NOGA 90-93 | AW11: NOGA 94-96 | AY11: NOGA 97-98 | BC11: D21 | BE11: D31
A12: 1980 | B12: 1 | C12: 49949.522
A13: 1980 | B13: 2 | C13: 51718.735
A14: 1980 | B14: 3 | C14: 52002.73
A15: 1980 | B15: 4 | C15: 54793.818
A16: 1981 | B16: 1 | C16: 52977.659 | D16: 0.060623949
A17: 1981 | B17: 2 | C17: 55522.014 | D17: 0.073537736
A18: 1981 | B18: 3 | C18: 56051.232 | D18: 0.077851716
A19: 1981 | B19: 4 | C19: 59242.518 | D19: 0.081189828
A20: 1982 | B20: 1 | C20: 57055.029 | D20: 0.076963957
A21: 1982 | B21: 2 | C21: 59324.427 | D21: 0.068484787
A22: 1982 | B22: 3 | C22: 59074.572 | D22: 0.053938874
A23: 1982 | B23: 4 | C23: 61638.11 | D23: 0.040437042
A24: 1983 | B24: 1 | C24: 59277.027 | D24: 0.038944827
A25: 1983 | B25: 2 | C25: 60666.89 | D25: 0.022629169
A26: 1983 | B26: 3 | C26: 60588.291 | D26: 0.025623865
A27: 1983 | B27: 4 | C27: 63722.697 | D27: 0.033819774
... A51: 1989 | B51: 4 | C51: 90562.872 | D51: 0.073541637
A52: 1990 | B52: 1 | C52: 90810.988 | D52: 0.10290247 | E52: 88272.516 | G52: 1951.9506 | I52: 129.40888 | K52: 18024.624 | M52: 2949.9059 | O52: 15074.718 | Q52: 1493.405 | S52: 720.45477 | U52: 7013.395 | W52: 14302.411 | Y52: 4842.7938 | AA52: 3683.9388 | AC52: 1913.6717 | AE52: 4076.9261 | AG52: 6958.1677 | AI52: 2957.0858 | AK52: 3787.8453 | AM52: 12555.49 | AO52: 5678.8525 | AQ52: 3838.8594 | AS52: 3850.4828 | AU52: 298.94116 | AW52: 1489.598 | AY52: 291.93879 | BA52: 2538.4717 | BC52: 4545.6188 | BE52: -2007.1472
A53: 1990 | B53: 2 | C53: 93568.518 | D53: 0.085344841 | E53: 91113.438 | G53: 1947.6899 | I53: 138.59224 | K53: 18553.484 | M53: 2960.5586 | O53: 15592.926 | Q53: 1601.2024 | S53: 736.64237 | U53: 7468.2588 | W53: 15337.666 | Y53: 5190.9114 | AA53: 3691.784 | AC53: 1973.7205 | AE53: 4109.7071 | AG53: 6872.073 | AI53: 2785.0537 | AK53: 3879.2698 | AM53: 12822.731 | AO53: 5861.1524 | AQ53: 3946.0732 | AS53: 3925.6295 | AU53: 298.86514 | AW53: 1525.7537 | AY53: 302.41233 | BA53: 2455.0799 | BC53: 4425.4729 | BE53: -1970.3929
A54: 1990 | B54: 3 | C54: 93527.046 | D54: 0.081758201 | E54: 90971.409 | G54: 1944.4447 | I54: 138.66314 | K54: 18060.898 | M54: 2920.4214 | O54: 15140.477 | Q54: 1508.651 | S54: 742.80554 | U54: 7699.9588 | W54: 14320.738 | Y54: 4946.4442 | AA54: 3734.5054 | AC54: 2320.8762 | AE54: 4178.9786 | AG54: 6954.9954 | AI54: 2811.5136 | AK54: 3937.7474 | AM54: 13085.081 | AO54: 5998.2558 | AQ54: 4098.9863 | AS54: 3997.3805 | AU54: 318.40034 | AW54: 1556.8231 | AY54: 310.96731 | BA54: 2555.6365 | BC54: 4559.9426 | BE54: -2004.3061
A55: 1990 | B55: 4 | C55: 96855.485 | D55: 0.069483361 | E55: 94516.167 | G55: 1933.8518 | I55: 139.69676 | K55: 19244.463 | M55: 2983.8602 | O55: 16260.603 | Q55: 1703.2632 | S55: 738.84543 | U55: 6674.003 | W55: 17299.887 | Y55: 5993.6615 | AA55: 3861.927 | AC55: 1891.6143 | AE55: 4233.1918 | AG55: 6841.2458 | AI55: 2677.4674 | AK55: 3962.7774 | AM55: 13382.224 | AO55: 6154.8709 | AQ55: 4203.3974 | AS55: 4014.7775 | AU55: 334.20289 | AW55: 1546.9142 | AY55: 317.79065 | BA55: 2339.3177 | BC55: 4381.085 | BE55: -2041.7673
A56: 1991 | B56: 1 | C56: 95642.069 | D56: 0.053199304 | E56: 93139.096 | F56: 0.055131314 | G56: 1918.427 | H56: -0.017174403 | I56: 139.81937 | J56: 0.08044646 | K56: 18726.292 | L56: 0.038928323 | M56: 3117.8616 | N56: 0.056935952 | O56: 15608.431 | P56: 0.035404489 | Q56: 1811.8162 | R56: 0.2132116 | S56: 732.58471 | T56: 0.016836496 | U56: 7270.6178 | V56: 0.036675922 | W56: 13991.105 | X56: -0.021765936 | Y56: 4872.3806 | Z56: 0.0061094409 | AA56: 4149.2908 | AB56: 0.12631916 | AC56: 2194.6955 | AD56: 0.14685058 | AE56: 4406.9816 | AF56: 0.080956932 | AG56: 7333.957 | AH56: 0.054006933 | AI56: 3161.7736 | AJ56: 0.069219427 | AK56: 3953.2416 | AL56: 0.043665023 | AM56: 13675.715 | AN56: 0.089221854 | AO56: 6295.7152 | AP56: 0.10862453 | AQ56: 4172.7684 | AR56: 0.086981299 | AS56: 4095.0336 | AT56: 0.063511722 | AU56: 366.5919 | AV56: 0.22630119 | AW56: 1534.9562 | AX56: 0.030449971 | AY56: 322.72863 | AZ56: 0.10546676 | BA56: 2502.9732 | BB56: -0.013984184 | BC56: 4685.0349 | BD56: 0.030670429 | BE56: -2182.0617 | BF56: 0.087145844
A57: 1991 | B57: 2 | C57: 97602.376 | D57: 0.043111278 | E57: 95412.979 | F57: 0.047188881 | G57: 1939.2915 | H57: -0.0043119722 | I57: 152.30202 | J57: 0.098921713 | K57: 19405.177 | L57: 0.045904731 | M57: 3155.3364 | N57: 0.0657909 | O57: 16249.841 | P57: 0.042129034 | Q57: 1761.523 | R57: 0.1001251 | S57: 727.12184 | T57: -0.01292423 | U57: 7611.9823 | V57: 0.019244584 | W57: 14398.761 | X57: -0.06121567 | Y57: 4981.8762 | Z57: -0.040269477 | AA57: 4450.0656 | AB57: 0.20539709 | AC57: 2129.518 | AD57: 0.078935984 | AE57: 4517.7465 | AF57: 0.099286718 | AG57: 7420.143 | AH57: 0.079753228 | AI57: 3227.1742 | AJ57: 0.1587476 | AK57: 3953.1093 | AL57: 0.019034378 | AM57: 13913.111 | AN57: 0.085034968 | AO57: 6403.9119 | AP57: 0.092602865 | AQ57: 4121.0556 | AR57: 0.04434343 | AS57: 4223.0561 | AT57: 0.075765332 | AU57: 381.71976 | AV57: 0.27723078 | AW57: 1528.2693 | AX57: 0.0016487841 | AY57: 328.22347 | AZ57: 0.085350811 | BA57: 2189.3972 | BB57: -0.10821755 | BC57: 4461.9866 | BD57: 0.0082508032 | BE57: -2272.5894 | BF57: 0.15336862
A58: 1991 | B58: 3 | C58: 97494.694 | D58: 0.042422466 | E58: 95231.688 | F58: 0.046830958 | G58: 1911.0484 | H58: -0.017175243 | I58: 148.46829 | J58: 0.070711983 | K58: 18878.051 | L58: 0.045244286 | M58: 3146.9898 | N58: 0.077580728 | O58: 15731.061 | P58: 0.039006964 | Q58: 1795.1199 | R58: 0.18988416 | S58: 723.62255 | T58: -0.02582504 | U58: 7675.5017 | V58: -0.0031762689 | W58: 13528.56 | X58: -0.055316836 | Y58: 4777.105 | Z58: -0.034234539 | AA58: 4614.2218 | AB58: 0.23556438 | AC58: 2496.3819 | AD58: 0.075620477 | AE58: 4568.0865 | AF58: 0.093110787 | AG58: 7386.6121 | AH58: 0.062058517 | AI58: 3180.1819 | AJ58: 0.13112806 | AK58: 3960.3219 | AL58: 0.005732844 | AM58: 14165.49 | AN58: 0.082567944 | AO58: 6509.8712 | AP58: 0.085294036 | AQ58: 4166.3677 | AR58: 0.016438554 | AS58: 4392.9415 | AT58: 0.098955037 | AU58: 401.27689 | AV58: 0.26029037 | AW58: 1535.8993 | AX58: -0.013440081 | AY58: 334.16771 | AZ58: 0.074607212 | BA58: 2263.0061 | BB58: -0.11450392 | BC58: 4609.4528 | BD58: 0.010857628 | BE58: -2346.4467 | BF58: 0.17070275
A59: 1991 | B59: 4 | C59: 100676.39 | D59: 0.039449529 | E59: 98639.38 | F59: 0.043624418 | G59: 1873.8664 | H59: -0.031018586 | I59: 140.49173 | J59: 0.005690664 | K59: 19843.495 | L59: 0.031127468 | M59: 3237.7625 | N59: 0.0850919 | O59: 16605.732 | P59: 0.021224864 | Q59: 1973.0224 | R59: 0.15837784 | S59: 720.4455 | T59: -0.024903635 | U59: 6575.944 | V59: -0.014692692 | W59: 17041.765 | X59: -0.014920434 | Y59: 6001.6702 | Z59: 0.0013362011 | AA59: 4548.4121 | AB59: 0.17775714 | AC59: 2000.372 | AD59: 0.057494661 | AE59: 4565.0013 | AF59: 0.078382819 | AG59: 7340.0366 | AH59: 0.07290936 | AI59: 3123.5776 | AJ59: 0.16661646 | AK59: 3973.0107 | AL59: 0.0025823467 | AM59: 14411.801 | AN59: 0.076936112 | AO59: 6640.8896 | AP59: 0.078964877 | AQ59: 4298.6548 | AR59: 0.022661986 | AS59: 4413.5903 | AT59: 0.099336202 | AU59: 400.77094 | AV59: 0.19918455 | AW59: 1510.9039 | AX59: -0.023278765 | AY59: 339.91807 | AZ59: 0.069628892 | BA59: 2037.0082 | BB59: -0.12922979 | BC59: 4384.6193 | BD59: 0.00080670935 | BE59: -2347.6111 | BF59: 0.14979366
A60: 1992 | B60: 1 | C60: 98942.184 | D60: 0.034504846 | E60: 96581.358 | F60: 0.036958294 | G60: 1816.5036 | H60: -0.053128649 | I60: 125.6223 | J60: -0.10153868 | K60: 19347.074 | L60: 0.0331503 | M60: 3407.5282 | N60: 0.092905528 | O60: 15939.546 | P60: 0.021213896 | Q60: 1992.926 | R60: 0.099960347 | S60: 721.82975 | T60: -0.014680839 | U60: 6878.7515 | V60: -0.053897243 | W60: 14144.647 | X60: 0.010974256 | Y60: 4866.0189 | Z60: -0.0013056708 | AA60: 4457.3207 | AB60: 0.074236748 | AC60: 2282.5076 | AD60: 0.040011057 | AE60: 4597.2487 | AF60: 0.043174029 | AG60: 7762.8222 | AH60: 0.058476634 | AI60: 3526.3438 | AJ60: 0.11530559 | AK60: 3989.3235 | AL60: 0.009127169 | AM60: 14652.245 | AN60: 0.071406163 | AO60: 6786.7912 | AP60: 0.07800162 | AQ60: 4285.3107 | AR60: 0.02697066 | AS60: 4484.7414 | AT60: 0.095165956 | AU60: 393.76361 | AV60: 0.074119778 | AW60: 1507.2731 | AX60: -0.018035154 | AY60: 343.97931 | AZ60: 0.065846882 | BA60: 2360.826 | BB60: -0.056791339 | BC60: 4729.1993 | BD60: 0.0094267053 | BE60: -2368.3733 | BF60: 0.085383307
A61: 1992 | B61: 2 | C61: 100200.69 | D61: 0.026621419 | E61: 98124.428 | F61: 0.028418037 | G61: 1798.1483 | H61: -0.072780793 | I61: 129.30096 | J61: -0.15102267 | K61: 19512.026 | L61: 0.0055061848 | M61: 3393.1935 | N61: 0.075382508 | O61: 16118.832 | P61: -0.0080621516 | Q61: 2025.3122 | R61: 0.14975064 | S61: 721.10748 | T61: -0.0082714551 | U61: 7134.6634 | V61: -0.062706255 | W61: 15093.836 | X61: 0.048273266 | Y61: 5180.0268 | Z61: 0.03977431 | AA61: 4509.7678 | AB61: 0.013416016 | AC61: 2201.4919 | AD61: 0.033798182 | AE61: 4579.783 | AF61: 0.013731754 | AG61: 7563.3486 | AH61: 0.019299573 | AI61: 3290.6072 | AJ61: 0.019655879 | AK61: 4020.96 | AL61: 0.017163886 | AM61: 14848.743 | AN61: 0.067248191 | AO61: 6870.4665 | AP61: 0.072854623 | AQ61: 4247.6366 | AR61: 0.030715666 | AS61: 4608.1007 | AT61: 0.09117677 | AU61: 389.74481 | AV61: 0.021023395 | AW61: 1543.19 | AX61: 0.0097631285 | AY61: 347.76199 | AZ61: 0.059528087 | BA61: 2076.2614 | BB61: -0.051674412 | BC61: 4447.7936 | BD61: -0.003180859 | BE61: -2371.5322 | BF61: 0.043537501
A62: 1992 | B62: 3 | C62: 98954.02 | D62: 0.014968265 | E62: 96896.775 | F62: 0.017484593 | G62: 1790.9087 | H62: -0.062865849 | I62: 127.7174 | J62: -0.13976648 | K62: 18906.952 | L62: 0.0015309404 | M62: 3326.5891 | N62: 0.0570702 | O62: 15580.363 | P62: -0.0095796567 | Q62: 2141.1376 | R62: 0.19275462 | S62: 715.57693 | T62: -0.011118533 | U62: 7096.2614 | V62: -0.075466116 | W62: 14178.809 | X62: 0.048064966 | Y62: 4916.1377 | Z62: 0.02910397 | AA62: 4513.5845 | AB62: -0.021810243 | AC62: 2525.1089 | AD62: 0.011507448 | AE62: 4541.857 | AF62: -0.0057419085 | AG62: 7634.8403 | AH62: 0.03360515 | AI62: 3316.7932 | AJ62: 0.042957074 | AK62: 4072.1506 | AL62: 0.028237281 | AM62: 14841.471 | AN62: 0.047720295 | AO62: 6866.1323 | AP62: 0.054726295 | AQ62: 4347.5473 | AR62: 0.043486221 | AS62: 4465.0027 | AT62: 0.016403856 | AU62: 344.67897 | AV62: -0.14104454 | AW62: 1508.1762 | AX62: -0.018050091 | AY62: 351.01236 | AZ62: 0.050407756 | BA62: 2057.2452 | BB62: -0.090923717 | BC62: 4440.6638 | BD62: -0.036618018 | BE62: -2383.4186 | BF62: 0.015756548
A63: 1992 | B63: 4 | C63: 101459.97 | D63: 0.0077831729 | E63: 99432.564 | F63: 0.0080412528 | G63: 1729.5901 | H63: -0.076993923 | I63: 125.58933 | J63: -0.10607312 | K63: 19452.709 | L63: -0.019693377 | M63: 3368.8889 | N63: 0.040499074 | O63: 16083.82 | P63: -0.031429617 | Q63: 2154.7632 | R63: 0.092112879 | S63: 711.20116 | T63: -0.012831411 | U63: 6394.5509 | V63: -0.027584335 | W63: 17076.219 | X63: 0.0020217077 | Y63: 6012.3374 | Z63: 0.0017773622 | AA63: 4364.6753 | AB63: -0.040395811 | AC63: 2007.1115 | AD63: 0.0033691006 | AE63: 4460.1878 | AF63: -0.022960236 | AG63: 8132.8549 | AH63: 0.10801284 | AI63: 3727.0206 | AJ63: 0.1931897 | AK63: 4145.7835 | AL63: 0.043486627 | AM63: 14810.499 | AN63: 0.027664708 | AO63: 6847.5246 | AP63: 0.031115569 | AQ63: 4528.2697 | AR63: 0.053415534 | AS63: 4488.0921 | AT63: 0.016880097 | AU63: 328.60912 | AV63: -0.18005751 | AW63: 1467.3698 | AX63: -0.028813298 | AY63: 352.74803 | AZ63: 0.037744296 | BA63: 2027.4057 | BB63: -0.0047139987 | BC63: 4387.4382 | BD63: 0.00064290706 | BE63: -2360.0325 | BF63: 0.0052910623
A64: 1993 | B64: 1 | C64: 98779.554 | D64: -0.0016436845 | E64: 96371.297 | F64: -0.0021749684 | G64: 1715.3907 | H64: -0.055663455 | I64: 122.39516 | J64: -0.025689171 | K64: 18929.378 | L64: -0.021589654 | M64: 3543.9363 | N64: 0.040031397 | O64: 15385.441 | P64: -0.034762894 | Q64: 2142.3482 | R64: 0.074976285 | S64: 701.30329 | T64: -0.028436698 | U64: 6340.1253 | V64: -0.078302903 | W64: 13710.959 | X64: -0.030660925 | Y64: 4790.7949 | Z64: -0.015459049 | AA64: 4207.1979 | AB64: -0.056115045 | AC64: 2311.5998 | AD64: 0.012745685 | AE64: 4425.0902 | AF64: -0.037448157 | AG64: 8818.8224 | AH64: 0.13603303 | AI64: 4290.3094 | AJ64: 0.21664524 | AK64: 4243.6159 | AL64: 0.063743224 | AM64: 14797.38 | AN64: 0.0099053201 | AO64: 6890.8525 | AP64: 0.015332923 | AQ64: 4603.0193 | AR64: 0.074138991 | AS64: 4516.7392 | AT64: 0.0071348258 | AU64: 328.98996 | AV64: -0.1644988 | AW64: 1455.2975 | AX64: -0.034483211 | AY64: 354.40815 | AZ64: 0.030318241 | BA64: 2408.2577 | BB64: 0.020091132 | BC64: 4776.4885 | BD64: 0.0099993938 | BE64: -2368.2308 | BF64: -6.0184731e-05
A65: 1993 | B65: 2 | C65: 101557.58 | D65: 0.013541746 | E65: 99295.674 | F65: 0.01193633 | G65: 1664.3749 | H65: -0.074395068 | I65: 130.96422 | J65: 0.012863519 | K65: 19485.24 | L65: -0.0013727543 | M65: 3625.0214 | N65: 0.068321444 | O65: 15860.219 | P65: -0.016044159 | Q65: 2158.0187 | R65: 0.065523961 | S65: 692.38523 | T65: -0.039830748 | U65: 6702.048 | V65: -0.060635715 | W65: 14678.274 | X65: -0.027531879 | Y65: 5109.665 | Z65: -0.013583299 | AA65: 4173.6451 | AB65: -0.07453216 | AC65: 2223.6783 | AD65: 0.010077896 | AE65: 4456.7758 | AF65: -0.026858759 | AG65: 9351.1607 | AH65: 0.23637838 | AI65: 4782.7648 | AJ65: 0.45345967 | AK65: 4265.2978 | AL65: 0.060766014 | AM65: 15244.359 | AN65: 0.026643098 | AO65: 6969.0116 | AP65: 0.014343285 | AQ65: 4563.861 | AR65: 0.074447154 | AS65: 4603.6518 | AT65: -0.00096545947 | AU65: 348.17924 | AV65: -0.10664816 | AW65: 1492.2036 | AX65: -0.033039623 | AY65: 357.84208 | AZ65: 0.028985608 | BA65: 2261.9082 | BB65: 0.089413986 | BC65: 4626.3508 | BD65: 0.040145126 | BE65: -2364.4426 | BF65: -0.0029894476
A66: 1993 | B66: 3 | C66: 102202.9 | D66: 0.03283222 | E66: 99895.237 | F66: 0.030944914 | G66: 1668.9876 | H66: -0.068077803 | I66: 129.83548 | J66: 0.016584162 | K66: 19239.644 | L66: 0.017596249 | M66: 3563.4997 | N66: 0.071217261 | O66: 15676.144 | P66: 0.006147538 | Q66: 2358.548 | R66: 0.10153971 | S66: 728.64718 | T66: 0.018265327 | U66: 6844.8512 | V66: -0.035428542 | W66: 14155.844 | X66: -0.0016196701 | Y66: 4971.2307 | Z66: 0.011206556 | AA66: 4145.0816 | AB66: -0.08164307 | AC66: 2551.4073 | AD66: 0.01041473 | AE66: 4425.9943 | AF66: -0.025509975 | AG66: 9766.6479 | AH66: 0.27922099 | AI66: 5232.2712 | AJ66: 0.57750902 | AK66: 4209.0584 | AL66: 0.033620509 | AM66: 15479.102 | AN66: 0.042962757 | AO66: 6999.7026 | AP66: 0.019453499 | AQ66: 4549.8958 | AR66: 0.046543147 | AS66: 4644.9232 | AT66: 0.040295733 | AU66: 344.54963 | AV66: -0.00037525837 | AW66: 1499.0711 | AX66: -0.0060371767 | AY66: 362.50497 | AZ66: 0.032741349 | BA66: 2307.6629 | BB66: 0.12172477 | BC66: 4681.7426 | BD66: 0.054288905 | BE66: -2374.0797 | BF66: -0.0039182901
A67: 1993 | B67: 4 | C67: 105779.57 | D67: 0.042574419 | E67: 103448.72 | F67: 0.040390778 | G67: 1614.9369 | H67: -0.066289221 | I67: 124.11649 | J67: -0.011727479 | K67: 20351.96 | L67: 0.04622751 | M67: 3629.8266 | N67: 0.077455113 | O67: 16722.133 | P67: 0.039686631 | Q67: 2596.411 | R67: 0.20496352 | S67: 712.79485 | T67: 0.002240835 | U67: 6512.0773 | V67: 0.018379144 | W67: 16993.996 | X67: -0.0048150313 | Y67: 5977.5547 | Z67: -0.0057852143 | AA67: 4087.0548 | AB67: -0.063606218 | AC67: 2018.2405 | AD67: 0.0055447907 | AE67: 4408.8349 | AF67: -0.011513613 | AG67: 9831.8182 | AH67: 0.20890123 | AI67: 5405.6066 | AJ67: 0.4503828 | AK67: 4071.9024 | AL67: -0.017820773 | AM67: 15676.144 | AN67: 0.058448034 | AO67: 7087.1169 | AP67: 0.034989614 | AQ67: 4516.9847 | AR67: -0.0024921303 | AS67: 4670.3505 | AT67: 0.040609327 | AU67: 381.45545 | AV67: 0.1608182 | AW67: 1495.4634 | AX67: 0.01914554 | AY67: 368.96795 | AZ67: 0.045981589 | BA67: 2330.8463 | BB67: 0.14966941 | BC67: 4659.697 | BD67: 0.062054162 | BE67: -2328.8507 | BF67: -0.013212449
...

Sheet real_q
A1: =INDIRECT("beschriftung!"&ADDRESS(beschriftung!$C$1*12+ROW(beschriftung!$A1)-1,COLUMN(beschriftung!A$1))) -> ESA 2010, Quarterly aggregates of Gross Domestic Product, production approach, raw data
A2: =INDIRECT("beschriftung!"&ADDRESS(beschriftung!$C$1*12+ROW(beschriftung!$A3)-1,COLUMN(beschriftung!A$1))) -> In Mio. Swiss Francs, at prices of the preceding year, chained values ("annual overlap"), reference year 2020, percentage change to previous year
C4: =INDIRECT("beschriftung!"&ADDRESS(beschriftung!$C$1*12+ROW(beschriftung!$A5)-1,COLUMN(beschriftung!C$1))) -> Gross domestic product | D4: =IF(INDIRECT("beschriftung.!"&ADDRESS(#REF!*12+ROW($A5)-1,COLUMN(D$1)))="","",INDIRECT("beschriftung.!"&ADDRESS(#REF!*12+ROW($A5)-1,COLUMN(D$1)))) -> #REF! | E4: =IF(INDIRECT("beschriftung.!"&ADDRESS(#REF!*12+ROW($A5)-1,COLUMN(E$1)))="","",INDIRECT("beschriftung.!"&ADDRESS(#REF!*12+ROW($A5)-1,COLUMN(E$1)))) -> #REF! | F4: =IF(INDIRECT("beschriftung.!"&ADDRESS(#REF!*12+ROW($A5)-1,COLUMN(F$1)))="","",INDIRECT("beschriftung.!"&ADDRESS(#REF!*12+ROW($A5)-1,COLUMN(F$1)))) -> #REF! | G4: =IF(INDIRECT("beschriftung.!"&ADDRESS(#REF!*12+ROW($A5)-1,COLUMN(G$1)))="","",INDIRECT("beschriftung.!"&ADDRESS(#REF!*12+ROW($A5)-1,COLUMN(G$1)))) -> #REF! | H4: =IF(INDIRECT("beschriftung.!"&ADDRESS(#REF!*12+ROW($A5)-1,COLUMN(H$1)))="","",INDIRECT("beschriftung.!"&ADDRESS(#REF!*12+ROW($A5)-1,COLUMN(H$1)))) -> #REF! | I4: =IF(INDIRECT("beschriftung.!"&ADDRESS(#REF!*12+ROW($A5)-1,COLUMN(I$1)))="","",INDIRECT("beschriftung.!"&ADDRESS(#REF!*12+ROW($A5)-1,COLUMN(I$1)))) -> #REF! | J4: =IF(INDIRECT("beschriftung.!"&ADDRESS(#REF!*12+ROW($A5)-1,COLUMN(J$1)))="","",INDIRECT("beschriftung.!"&ADDRESS(#REF!*12+ROW($A5)-1,COLUMN(J$1)))) -> #REF! | K4: =IF(INDIRECT("beschriftung.!"&ADDRESS(#REF!*12+ROW($A5)-1,COLUMN(K$1)))="","",INDIRECT("beschriftung.!"&ADDRESS(#REF!*12+ROW($A5)-1,COLUMN(K$1)))) -> #REF! | L4: =IF(INDIRECT("beschriftung.!"&ADDRESS(#REF!*12+ROW($A5)-1,COLUMN(L$1)))="","",INDIRECT("beschriftung.!"&ADDRESS(#REF!*12+ROW($A5)-1,COLUMN(L$1)))) -> #REF! | Q4: =IF(INDIRECT("beschriftung.!"&ADDRESS(#REF!*12+ROW($A5)-1,COLUMN(Q$1)))="","",INDIRECT("beschriftung.!"&ADDRESS(#REF!*12+ROW($A5)-1,COLUMN(Q$1)))) -> #REF! | R4: =IF(INDIRECT("beschriftung.!"&ADDRESS(#REF!*12+ROW($A5)-1,COLUMN(R$1)))="","",INDIRECT("beschriftung.!"&ADDRESS(#REF!*12+ROW($A5)-1,COLUMN(R$1)))) -> #REF! | U4: =IF(INDIRECT("beschriftung.!"&ADDRESS(#REF!*12+ROW($A5)-1,COLUMN(U$1)))="","",INDIRECT("beschriftung.!"&ADDRESS(#REF!*12+ROW($A5)-1,COLUMN(U$1)))) -> #REF! | V4: =IF(INDIRECT("beschriftung.!"&ADDRESS(#REF!*12+ROW($A5)-1,COLUMN(V$1)))="","",INDIRECT("beschriftung.!"&ADDRESS(#REF!*12+ROW($A5)-1,COLUMN(V$1)))) -> #REF! | W4: =IF(INDIRECT("beschriftung.!"&ADDRESS(#REF!*12+ROW($A5)-1,COLUMN(W$1)))="","",INDIRECT("beschriftung.!"&ADDRESS(#REF!*12+ROW($A5)-1,COLUMN(W$1)))) -> #REF! | X4: =IF(INDIRECT("beschriftung.!"&ADDRESS(#REF!*12+ROW($A5)-1,COLUMN(X$1)))="","",INDIRECT("beschriftung.!"&ADDRESS(#REF!*12+ROW($A5)-1,COLUMN(X$1)))) -> #REF! | AA4: =IF(INDIRECT("beschriftung.!"&ADDRESS(#REF!*12+ROW($A5)-1,COLUMN(AA$1)))="","",INDIRECT("beschriftung.!"&ADDRESS(#REF!*12+ROW($A5)-1,COLUMN(AA$1)))) -> #REF! | AB4: =IF(INDIRECT("beschriftung.!"&ADDRESS(#REF!*12+ROW($A5)-1,COLUMN(AB$1)))="","",INDIRECT("beschriftung.!"&ADDRESS(#REF!*12+ROW($A5)-1,COLUMN(AB$1)))) -> #REF! | AG4: =IF(INDIRECT("beschriftung.!"&ADDRESS(#REF!*12+ROW($A5)-1,COLUMN(AG$1)))="","",INDIRECT("beschriftung.!"&ADDRESS(#REF!*12+ROW($A5)-1,COLUMN(AG$1)))) -> #REF! | AH4: =IF(INDIRECT("beschriftung.!"&ADDRESS(#REF!*12+ROW($A5)-1,COLUMN(AH$1)))="","",INDIRECT("beschriftung.!"&ADDRESS(#REF!*12+ROW($A5)-1,COLUMN(AH$1)))) -> #REF! | AI4: =IF(INDIRECT("beschriftung.!"&ADDRESS(#REF!*12+ROW($A5)-1,COLUMN(AI$1)))="","",INDIRECT("beschriftung.!"&ADDRESS(#REF!*12+ROW($A5)-1,COLUMN(AI$1)))) -> #REF! | AJ4: =IF(INDIRECT("beschriftung.!"&ADDRESS(#REF!*12+ROW($A5)-1,COLUMN(AJ$1)))="","",INDIRECT("beschriftung.!"&ADDRESS(#REF!*12+ROW($A5)-1,COLUMN(AJ$1)))) -> #REF! | AM4: =IF(INDIRECT("beschriftung.!"&ADDRESS(#REF!*12+ROW($A5)-1,COLUMN(AM$1)))="","",INDIRECT("beschriftung.!"&ADDRESS(#REF!*12+ROW($A5)-1,COLUMN(AM$1)))) -> #REF! | AN4: =IF(INDIRECT("beschriftung.!"&ADDRESS(#REF!*12+ROW($A5)-1,COLUMN(AN$1)))="","",INDIRECT("beschriftung.!"&ADDRESS(#REF!*12+ROW($A5)-1,COLUMN(AN$1)))) -> #REF! | AO4: =IF(INDIRECT("beschriftung.!"&ADDRESS(#REF!*12+ROW($A5)-1,COLUMN(AO$1)))="","",INDIRECT("beschriftung.!"&ADDRESS(#REF!*12+ROW($A5)-1,COLUMN(AO$1)))) -> #REF! | AP4: =IF(INDIRECT("beschriftung.!"&ADDRESS(#REF!*12+ROW($A5)-1,COLUMN(AP$1)))="","",INDIRECT("beschriftung.!"&ADDRESS(#REF!*12+ROW($A5)-1,COLUMN(AP$1)))) -> #REF! | AQ4: =IF(INDIRECT("beschriftung.!"&ADDRESS(#REF!*12+ROW($A5)-1,COLUMN(AQ$1)))="","",INDIRECT("beschriftung.!"&ADDRESS(#REF!*12+ROW($A5)-1,COLUMN(AQ$1)))) -> #REF! | AR4: =IF(INDIRECT("beschriftung.!"&ADDRESS(#REF!*12+ROW($A5)-1,COLUMN(AR$1)))="","",INDIRECT("beschriftung.!"&ADDRESS(#REF!*12+ROW($A5)-1,COLUMN(AR$1)))) -> #REF! | AS4: =IF(INDIRECT("beschriftung.!"&ADDRESS(#REF!*12+ROW($A5)-1,COLUMN(AS$1)))="","",INDIRECT("beschriftung.!"&ADDRESS(#REF!*12+ROW($A5)-1,COLUMN(AS$1)))) -> #REF! | AT4: =IF(INDIRECT("beschriftung.!"&ADDRESS(#REF!*12+ROW($A5)-1,COLUMN(AT$1)))="","",INDIRECT("beschriftung.!"&ADDRESS(#REF!*12+ROW($A5)-1,COLUMN(AT$1)))) -> #REF! | ... AV4: =IF(INDIRECT("beschriftung.!"&ADDRESS(#REF!*12+ROW($A5)-1,COLUMN(AV$1)))="","",INDIRECT("beschriftung.!"&ADDRESS(#REF!*12+ROW($A5)-1,COLUMN(AV$1)))) -> #REF! | AY4: =IF(INDIRECT("beschriftung.!"&ADDRESS(#REF!*12+ROW($A5)-1,COLUMN(AY$1)))="","",INDIRECT("beschriftung.!"&ADDRESS(#REF!*12+ROW($A5)-1,COLUMN(AY$1)))) -> #REF! | AZ4: =IF(INDIRECT("beschriftung.!"&ADDRESS(#REF!*12+ROW($A5)-1,COLUMN(AZ$1)))="","",INDIRECT("beschriftung.!"&ADDRESS(#REF!*12+ROW($A5)-1,COLUMN(AZ$1)))) -> #REF! | BA4: =IF(INDIRECT("beschriftung.!"&ADDRESS(#REF!*12+ROW($A5)-1,COLUMN(BA$1)))="","",INDIRECT("beschriftung.!"&ADDRESS(#REF!*12+ROW($A5)-1,COLUMN(BA$1)))) -> #REF! | BB4: =IF(INDIRECT("beschriftung.!"&ADDRESS(#REF!*12+ROW($A5)-1,COLUMN(BB$1)))="","",INDIRECT("beschriftung.!"&ADDRESS(#REF!*12+ROW($A5)-1,COLUMN(BB$1)))) -> #REF! | BC4: =IF(INDIRECT("beschriftung.!"&ADDRESS(#REF!*12+ROW($A5)-1,COLUMN(BC$1)))="","",INDIRECT("beschriftung.!"&ADDRESS(#REF!*12+ROW($A5)-1,COLUMN(BC$1)))) -> #REF! | BD4: =IF(INDIRECT("beschriftung.!"&ADDRESS(#REF!*12+ROW($A5)-1,COLUMN(BD$1)))="","",INDIRECT("beschriftung.!"&ADDRESS(#REF!*12+ROW($A5)-1,COLUMN(BD$1)))) -> #REF! | BE4: =IF(INDIRECT("beschriftung.!"&ADDRESS(#REF!*12+ROW($A5)-1,COLUMN(BE$1)))="","",INDIRECT("beschriftung.!"&ADDRESS(#REF!*12+ROW($A5)-1,COLUMN(BE$1)))) -> #REF! | BF4: =IF(INDIRECT("beschriftung.!"&ADDRESS(#REF!*12+ROW($A5)-1,COLUMN(BF$1)))="","",INDIRECT("beschriftung.!"&ADDRESS(#REF!*12+ROW($A5)-1,COLUMN(BF$1)))) -> #REF!
E5: =INDIRECT("beschriftung!"&ADDRESS(beschriftung!$C$1*12+ROW(beschriftung!$A6)-1,COLUMN(beschriftung!D$1))) -> Gross value added before adjustments | F5: =IF(INDIRECT("beschriftung.!"&ADDRESS(#REF!*12+ROW($A6)-1,COLUMN(F$1)))="","",INDIRECT("beschriftung.!"&ADDRESS(#REF!*12+ROW($A6)-1,COLUMN(F$1)))) -> #REF! | G5: =IF(INDIRECT("beschriftung.!"&ADDRESS(#REF!*12+ROW($A6)-1,COLUMN(G$1)))="","",INDIRECT("beschriftung.!"&ADDRESS(#REF!*12+ROW($A6)-1,COLUMN(G$1)))) -> #REF! | H5: =IF(INDIRECT("beschriftung.!"&ADDRESS(#REF!*12+ROW($A6)-1,COLUMN(H$1)))="","",INDIRECT("beschriftung.!"&ADDRESS(#REF!*12+ROW($A6)-1,COLUMN(H$1)))) -> #REF! | I5: =IF(INDIRECT("beschriftung.!"&ADDRESS(#REF!*12+ROW($A6)-1,COLUMN(I$1)))="","",INDIRECT("beschriftung.!"&ADDRESS(#REF!*12+ROW($A6)-1,COLUMN(I$1)))) -> #REF! | J5: =IF(INDIRECT("beschriftung.!"&ADDRESS(#REF!*12+ROW($A6)-1,COLUMN(J$1)))="","",INDIRECT("beschriftung.!"&ADDRESS(#REF!*12+ROW($A6)-1,COLUMN(J$1)))) -> #REF! | K5: =IF(INDIRECT("beschriftung.!"&ADDRESS(#REF!*12+ROW($A6)-1,COLUMN(K$1)))="","",INDIRECT("beschriftung.!"&ADDRESS(#REF!*12+ROW($A6)-1,COLUMN(K$1)))) -> #REF! | L5: =IF(INDIRECT("beschriftung.!"&ADDRESS(#REF!*12+ROW($A6)-1,COLUMN(L$1)))="","",INDIRECT("beschriftung.!"&ADDRESS(#REF!*12+ROW($A6)-1,COLUMN(L$1)))) -> #REF! | Q5: =IF(INDIRECT("beschriftung.!"&ADDRESS(#REF!*12+ROW($A6)-1,COLUMN(Q$1)))="","",INDIRECT("beschriftung.!"&ADDRESS(#REF!*12+ROW($A6)-1,COLUMN(Q$1)))) -> #REF! | R5: =IF(INDIRECT("beschriftung.!"&ADDRESS(#REF!*12+ROW($A6)-1,COLUMN(R$1)))="","",INDIRECT("beschriftung.!"&ADDRESS(#REF!*12+ROW($A6)-1,COLUMN(R$1)))) -> #REF! | U5: =IF(INDIRECT("beschriftung.!"&ADDRESS(#REF!*12+ROW($A6)-1,COLUMN(U$1)))="","",INDIRECT("beschriftung.!"&ADDRESS(#REF!*12+ROW($A6)-1,COLUMN(U$1)))) -> #REF! | V5: =IF(INDIRECT("beschriftung.!"&ADDRESS(#REF!*12+ROW($A6)-1,COLUMN(V$1)))="","",INDIRECT("beschriftung.!"&ADDRESS(#REF!*12+ROW($A6)-1,COLUMN(V$1)))) -> #REF! | W5: =IF(INDIRECT("beschriftung.!"&ADDRESS(#REF!*12+ROW($A6)-1,COLUMN(W$1)))="","",INDIRECT("beschriftung.!"&ADDRESS(#REF!*12+ROW($A6)-1,COLUMN(W$1)))) -> #REF! | X5: =IF(INDIRECT("beschriftung.!"&ADDRESS(#REF!*12+ROW($A6)-1,COLUMN(X$1)))="","",INDIRECT("beschriftung.!"&ADDRESS(#REF!*12+ROW($A6)-1,COLUMN(X$1)))) -> #REF! | AA5: =IF(INDIRECT("beschriftung.!"&ADDRESS(#REF!*12+ROW($A6)-1,COLUMN(AA$1)))="","",INDIRECT("beschriftung.!"&ADDRESS(#REF!*12+ROW($A6)-1,COLUMN(AA$1)))) -> #REF! | AB5: =IF(INDIRECT("beschriftung.!"&ADDRESS(#REF!*12+ROW($A6)-1,COLUMN(AB$1)))="","",INDIRECT("beschriftung.!"&ADDRESS(#REF!*12+ROW($A6)-1,COLUMN(AB$1)))) -> #REF! | AG5: =IF(INDIRECT("beschriftung.!"&ADDRESS(#REF!*12+ROW($A6)-1,COLUMN(AG$1)))="","",INDIRECT("beschriftung.!"&ADDRESS(#REF!*12+ROW($A6)-1,COLUMN(AG$1)))) -> #REF! | AH5: =IF(INDIRECT("beschriftung.!"&ADDRESS(#REF!*12+ROW($A6)-1,COLUMN(AH$1)))="","",INDIRECT("beschriftung.!"&ADDRESS(#REF!*12+ROW($A6)-1,COLUMN(AH$1)))) -> #REF! | AI5: =IF(INDIRECT("beschriftung.!"&ADDRESS(#REF!*12+ROW($A6)-1,COLUMN(AI$1)))="","",INDIRECT("beschriftung.!"&ADDRESS(#REF!*12+ROW($A6)-1,COLUMN(AI$1)))) -> #REF! | AJ5: =IF(INDIRECT("beschriftung.!"&ADDRESS(#REF!*12+ROW($A6)-1,COLUMN(AJ$1)))="","",INDIRECT("beschriftung.!"&ADDRESS(#REF!*12+ROW($A6)-1,COLUMN(AJ$1)))) -> #REF! | AM5: =IF(INDIRECT("beschriftung.!"&ADDRESS(#REF!*12+ROW($A6)-1,COLUMN(AM$1)))="","",INDIRECT("beschriftung.!"&ADDRESS(#REF!*12+ROW($A6)-1,COLUMN(AM$1)))) -> #REF! | AN5: =IF(INDIRECT("beschriftung.!"&ADDRESS(#REF!*12+ROW($A6)-1,COLUMN(AN$1)))="","",INDIRECT("beschriftung.!"&ADDRESS(#REF!*12+ROW($A6)-1,COLUMN(AN$1)))) -> #REF! | AO5: =IF(INDIRECT("beschriftung.!"&ADDRESS(#REF!*12+ROW($A6)-1,COLUMN(AO$1)))="","",INDIRECT("beschriftung.!"&ADDRESS(#REF!*12+ROW($A6)-1,COLUMN(AO$1)))) -> #REF! | AP5: =IF(INDIRECT("beschriftung.!"&ADDRESS(#REF!*12+ROW($A6)-1,COLUMN(AP$1)))="","",INDIRECT("beschriftung.!"&ADDRESS(#REF!*12+ROW($A6)-1,COLUMN(AP$1)))) -> #REF! | AQ5: =IF(INDIRECT("beschriftung.!"&ADDRESS(#REF!*12+ROW($A6)-1,COLUMN(AQ$1)))="","",INDIRECT("beschriftung.!"&ADDRESS(#REF!*12+ROW($A6)-1,COLUMN(AQ$1)))) -> #REF! | AR5: =IF(INDIRECT("beschriftung.!"&ADDRESS(#REF!*12+ROW($A6)-1,COLUMN(AR$1)))="","",INDIRECT("beschriftung.!"&ADDRESS(#REF!*12+ROW($A6)-1,COLUMN(AR$1)))) -> #REF! | AS5: =IF(INDIRECT("beschriftung.!"&ADDRESS(#REF!*12+ROW($A6)-1,COLUMN(AS$1)))="","",INDIRECT("beschriftung.!"&ADDRESS(#REF!*12+ROW($A6)-1,COLUMN(AS$1)))) -> #REF! | AT5: =IF(INDIRECT("beschriftung.!"&ADDRESS(#REF!*12+ROW($A6)-1,COLUMN(AT$1)))="","",INDIRECT("beschriftung.!"&ADDRESS(#REF!*12+ROW($A6)-1,COLUMN(AT$1)))) -> #REF! | ... AV5: =IF(INDIRECT("beschriftung.!"&ADDRESS(#REF!*12+ROW($A6)-1,COLUMN(AV$1)))="","",INDIRECT("beschriftung.!"&ADDRESS(#REF!*12+ROW($A6)-1,COLUMN(AV$1)))) -> #REF! | AY5: =IF(INDIRECT("beschriftung.!"&ADDRESS(#REF!*12+ROW($A6)-1,COLUMN(AY$1)))="","",INDIRECT("beschriftung.!"&ADDRESS(#REF!*12+ROW($A6)-1,COLUMN(AY$1)))) -> #REF! | AZ5: =IF(INDIRECT("beschriftung.!"&ADDRESS(#REF!*12+ROW($A6)-1,COLUMN(AZ$1)))="","",INDIRECT("beschriftung.!"&ADDRESS(#REF!*12+ROW($A6)-1,COLUMN(AZ$1)))) -> #REF! | BA5: =INDIRECT("beschriftung!"&ADDRESS(beschriftung!$C$1*12+ROW(beschriftung!$A6)-1,COLUMN(beschriftung!AS$1))) -> Adjustments | BB5: =IF(INDIRECT("beschriftung.!"&ADDRESS(#REF!*12+ROW($A6)-1,COLUMN(BB$1)))="","",INDIRECT("beschriftung.!"&ADDRESS(#REF!*12+ROW($A6)-1,COLUMN(BB$1)))) -> #REF! | BC5: =IF(INDIRECT("beschriftung.!"&ADDRESS(#REF!*12+ROW($A6)-1,COLUMN(BC$1)))="","",INDIRECT("beschriftung.!"&ADDRESS(#REF!*12+ROW($A6)-1,COLUMN(BC$1)))) -> #REF! | BD5: =IF(INDIRECT("beschriftung.!"&ADDRESS(#REF!*12+ROW($A6)-1,COLUMN(BD$1)))="","",INDIRECT("beschriftung.!"&ADDRESS(#REF!*12+ROW($A6)-1,COLUMN(BD$1)))) -> #REF! | BE5: =IF(INDIRECT("beschriftung.!"&ADDRESS(#REF!*12+ROW($A6)-1,COLUMN(BE$1)))="","",INDIRECT("beschriftung.!"&ADDRESS(#REF!*12+ROW($A6)-1,COLUMN(BE$1)))) -> #REF! | BF5: =IF(INDIRECT("beschriftung.!"&ADDRESS(#REF!*12+ROW($A6)-1,COLUMN(BF$1)))="","",INDIRECT("beschriftung.!"&ADDRESS(#REF!*12+ROW($A6)-1,COLUMN(BF$1)))) -> #REF!
G6: =INDIRECT("beschriftung!"&ADDRESS(beschriftung!$C$1*12+ROW(beschriftung!$A7)-1,COLUMN(beschriftung!E$1))) -> Agriculture, forestry and fishing | I6: =INDIRECT("beschriftung!"&ADDRESS(beschriftung!$C$1*12+ROW(beschriftung!$A7)-1,COLUMN(beschriftung!G$1))) -> Mining and quarrying | K6: =INDIRECT("beschriftung!"&ADDRESS(beschriftung!$C$1*12+ROW(beschriftung!$A7)-1,COLUMN(beschriftung!I$1))) -> Manufacturing | Q6: =INDIRECT("beschriftung!"&ADDRESS(beschriftung!$C$1*12+ROW(beschriftung!$A7)-1,COLUMN(beschriftung!M$1))) -> Electricity, gas, steam and air conditioning supply | S6: =INDIRECT("beschriftung!"&ADDRESS(beschriftung!$C$1*12+ROW(beschriftung!$A7)-1,COLUMN(beschriftung!O$1))) -> Water supply, sewerage, waste management and remediation activities | U6: =INDIRECT("beschriftung!"&ADDRESS(beschriftung!$C$1*12+ROW(beschriftung!$A7)-1,COLUMN(beschriftung!Q$1))) -> Construction | W6: =INDIRECT("beschriftung!"&ADDRESS(beschriftung!$C$1*12+ROW(beschriftung!$A7)-1,COLUMN(beschriftung!S$1))) -> Trade, repair of motor vehicles and motorcycles | AA6: =INDIRECT("beschriftung!"&ADDRESS(beschriftung!$C$1*12+ROW(beschriftung!$A7)-1,COLUMN(beschriftung!W$1))) -> Transportation and storage | AC6: =INDIRECT("beschriftung!"&ADDRESS(beschriftung!$C$1*12+ROW(beschriftung!$A7)-1,COLUMN(beschriftung!Y$1))) -> Accommodation and food service activities | AE6: =INDIRECT("beschriftung!"&ADDRESS(beschriftung!$C$1*12+ROW(beschriftung!$A7)-1,COLUMN(beschriftung!X$1))) -> Information and communication | AG6: =INDIRECT("beschriftung!"&ADDRESS(beschriftung!$C$1*12+ROW(beschriftung!$A7)-1,COLUMN(beschriftung!AA$1))) -> Financial and insurance activities | AM6: =INDIRECT("beschriftung!"&ADDRESS(beschriftung!$C$1*12+ROW(beschriftung!$A7)-1,COLUMN(beschriftung!AE$1))) -> Real estate, professional, scientific, technical activities and administrative services | AO6: =INDIRECT("beschriftung!"&ADDRESS(beschriftung!$C$1*12+ROW(beschriftung!$A7)-1,COLUMN(beschriftung!AG$1))) -> Public administration | AQ6: =INDIRECT("beschriftung!"&ADDRESS(beschriftung!$C$1*12+ROW(beschriftung!$A7)-1,COLUMN(beschriftung!AI$1))) -> Education | AS6: =INDIRECT("beschriftung!"&ADDRESS(beschriftung!$C$1*12+ROW(beschriftung!$A7)-1,COLUMN(beschriftung!AK$1))) -> Human health and social work activities | AU6: =INDIRECT("beschriftung!"&ADDRESS(beschriftung!$C$1*12+ROW(beschriftung!$A7)-1,COLUMN(beschriftung!AM$1))) -> Arts, entertainment and recreation | AW6: =INDIRECT("beschriftung!"&ADDRESS(beschriftung!$C$1*12+ROW(beschriftung!$A7)-1,COLUMN(beschriftung!AO$1))) -> Other service activities | AY6: =INDIRECT("beschriftung!"&ADDRESS(beschriftung!$C$1*12+ROW(beschriftung!$A7)-1,COLUMN(beschriftung!AQ$1))) -> Activities of housholds as employers and producers for own use | BC6: =INDIRECT("beschriftung!"&ADDRESS(beschriftung!$C$1*12+ROW(beschriftung!$A7)-1,COLUMN(beschriftung!AU$1))) -> Taxes on products | BE6: =INDIRECT("beschriftung!"&ADDRESS(beschriftung!$C$1*12+ROW(beschriftung!$A7)-1,COLUMN(beschriftung!AW$1))) -> Subsidies on products
M8: =INDIRECT("beschriftung!"&ADDRESS(beschriftung!$C$1*12+ROW(beschriftung!$A7),COLUMN(beschriftung!J$1))) -> thereof chemicals and pharmaceuticals | O8: =INDIRECT("beschriftung!"&ADDRESS(beschriftung!$C$1*12+ROW(beschriftung!$A7),COLUMN(beschriftung!K$1))) -> thereof other manufacturing | Y8: =INDIRECT("beschriftung!"&ADDRESS(beschriftung!$C$1*12+ROW(beschriftung!$A7),COLUMN(beschriftung!U$1))) -> thereof retail trade | AI8: =INDIRECT("beschriftung!"&ADDRESS(beschriftung!$C$1*12+ROW(beschriftung!$A7),COLUMN(beschriftung!AB$1))) -> thereof financial activities | AK8: =INDIRECT("beschriftung!"&ADDRESS(beschriftung!$C$1*12+ROW(beschriftung!$A7),COLUMN(beschriftung!AC$1))) -> thereof insurance activities
C11: B1GQ | E11: B1G | G11: NOGA 01-03 | I11: NOGA 05-09 | K11: NOGA 10-33 | M11: NOGA 19-21 | O11: NOGA 10-18; 22-33 | Q11: NOGA 35 | S11: NOGA 36-39 | U11: NOGA 41-43 | W11: NOGA 45-47 | Y11: NOGA 47 | AA11: NOGA 49-53 | AC11: NOGA 55-56 | AE11: NOGA 58-63 | AG11: NOGA 64-66 | AI11: NOGA 64 | AK11: NOGA 65 | AM11: NOGA 68-75; 77-82 | AO11: NOGA 84 | AQ11: NOGA 85 | AS11: NOGA 86-88 | AU11: NOGA 90-93 | AW11: NOGA 94-96 | AY11: NOGA 97-98 | BC11: D21 | BE11: D31
A12: 1980 | B12: 1 | C12: 89202.399
A13: 1980 | B13: 2 | C13: 91839.7
A14: 1980 | B14: 3 | C14: 91077.899
A15: 1980 | B15: 4 | C15: 95603.79
A16: 1981 | B16: 1 | C16: 90183.601 | D16: 0.010999723
A17: 1981 | B17: 2 | C17: 93716.463 | D17: 0.020435211
A18: 1981 | B18: 3 | C18: 92951.665 | D18: 0.020573229
A19: 1981 | B19: 4 | C19: 96760.551 | D19: 0.012099533
A20: 1982 | B20: 1 | C20: 90694.538 | D20: 0.0056655212
A21: 1982 | B21: 2 | C21: 92530.262 | D21: -0.012657346
A22: 1982 | B22: 3 | C22: 90924.24 | D22: -0.021811611
A23: 1982 | B23: 4 | C23: 94571.097 | D23: -0.02262755
A24: 1983 | B24: 1 | C24: 90386.127 | D24: -0.0034005457
A25: 1983 | B25: 2 | C25: 92476.622 | D25: -0.00057969777
A26: 1983 | B26: 3 | C26: 92015.746 | D26: 0.012004566
A27: 1983 | B27: 4 | C27: 96198.056 | D27: 0.017203556
... A51: 1989 | B51: 4 | C51: 114752.64 | D51: 0.035104722
A52: 1990 | B52: 1 | C52: 112647.09 | D52: 0.059643013 | E52: 110264.64 | G52: 1283.4175 | I52: 185.19496 | K52: 17376.43 | M52: 1360.5686 | O52: 19041.877 | Q52: 3292.8503 | S52: 316.41667 | U52: 9019.4671 | W52: 15629.081 | Y52: 4439.8349 | AA52: 5988.2867 | AC52: 3591.1296 | AE52: 4240.9433 | AG52: 6530.8012 | AI52: 3941.9496 | AK52: 2070.8627 | AM52: 22275.518 | AO52: 8574.5175 | AQ52: 6717.7655 | AS52: 5594.2969 | AU52: 729.23385 | AW52: 3265.4997 | AY52: 414.8191 | BA52: 2565.5777 | BC52: 5354.1077 | BE52: -2946.1081
A53: 1990 | B53: 2 | C53: 114837.06 | D53: 0.039481974 | E53: 112309.5 | G53: 1265.1256 | I53: 201.108 | K53: 17548.503 | M53: 1364.2104 | O53: 19257.508 | Q53: 3420.5697 | S53: 322.47115 | U53: 9477.8465 | W53: 16725.745 | Y53: 4749.4999 | AA53: 5885.6608 | AC53: 3612.5286 | AE53: 4252.763 | AG53: 6406.3478 | AI53: 3709.6681 | AK53: 2102.0849 | AM53: 22399.121 | AO53: 8697.2624 | AQ53: 6863.923 | AS53: 5632.9962 | AU53: 709.94437 | AW53: 3229.8747 | AY53: 422.28163 | BA53: 2705.064 | BC53: 5432.9246 | BE53: -2858.4613
A54: 1990 | B54: 3 | C54: 113855.43 | D54: 0.032301057 | E54: 111368.05 | G54: 1251.2669 | I54: 203.50678 | K54: 17088.056 | M54: 1340.8339 | O54: 18718.032 | Q54: 3326.6311 | S54: 331.04014 | U54: 9905.7591 | W54: 15505.686 | Y54: 4530.1973 | AA54: 5919.1684 | AC54: 4259.9741 | AE54: 4298.1488 | AG54: 6379.938 | AI54: 3623.0808 | AK54: 2127.4265 | AM54: 22527.481 | AO54: 8795.9304 | AQ54: 6930.3627 | AS54: 5635.6711 | AU54: 742.76229 | AW54: 3225.1164 | AY54: 426.4414 | BA54: 2665.0948 | BC54: 5398.2461 | BE54: -2869.4573
A55: 1990 | B55: 4 | C55: 116723.34 | D55: 0.017173436 | E55: 114171.08 | G55: 1248.3392 | I55: 205.40187 | K55: 18284.845 | M55: 1358.5916 | O55: 20238.614 | Q55: 3455.881 | S55: 341.43032 | U55: 8420.8577 | W55: 18395.35 | Y55: 5437.1447 | AA55: 5993.0191 | AC55: 3395.7088 | AE55: 4323.8954 | AG55: 6177.3011 | AI55: 3317.3289 | AK55: 2146.8686 | AM55: 22501.727 | AO55: 8867.3163 | AQ55: 6917.1463 | AS55: 5639.4367 | AU55: 769.77938 | AW55: 3117.5597 | AY55: 427.21225 | BA55: 2734.2387 | BC55: 5483.2402 | BE55: -2879.6244
A56: 1991 | B56: 1 | C56: 112414.74 | D56: -0.0020626473 | E56: 110130.59 | F56: -0.0012156642 | G56: 1245.9315 | H56: -0.029207911 | I56: 184.11832 | J56: -0.0058135622 | K56: 17471.392 | L56: 0.00546497 | M56: 1407.635 | N56: 0.034593202 | O56: 19039.329 | P56: -0.00013383604 | Q56: 3530.69 | R56: 0.072229115 | S56: 352.55696 | T56: 0.11421739 | U56: 8849.5391 | V56: -0.018840136 | W56: 14501.94 | X56: -0.072118196 | Y56: 4274.9005 | Z56: -0.03714876 | AA56: 6329.1579 | AB56: 0.056922995 | AC56: 3796.372 | AD56: 0.057152586 | AE56: 4341.0445 | AF56: 0.023603524 | AG56: 6606.2094 | AH56: 0.011546559 | AI56: 3857.579 | AJ56: -0.02140326 | AK56: 2160.1293 | AL56: 0.043105963 | AM56: 22524.397 | AN56: 0.011172775 | AO56: 8854.4642 | AP56: 0.032648684 | AQ56: 6824.2615 | AR56: 0.015852888 | AS56: 5654.8088 | AT56: 0.010816711 | AU56: 814.2285 | AV56: 0.11655335 | AW56: 2966.5854 | AX56: -0.091537065 | AY56: 424.46264 | AZ56: 0.023247565 | BA56: 2480.0613 | BB56: -0.033332243 | BC56: 5322.0845 | BD56: -0.0059810603 | BE56: -3025.4053 | BF56: 0.026915925
A57: 1991 | B57: 2 | C57: 113345.49 | D57: -0.012988537 | E57: 111122.11 | F57: -0.010572529 | G57: 1250.4509 | H57: -0.011599425 | I57: 204.51279 | J57: 0.016930165 | K57: 17780.168 | L57: 0.013201408 | M57: 1427.7621 | N57: 0.046584945 | O57: 19388.694 | P57: 0.0068122355 | Q57: 3368.8125 | R57: -0.015131145 | S57: 362.80708 | T57: 0.12508384 | U57: 9224.0311 | V57: -0.026779865 | W57: 14806.478 | X57: -0.11474929 | Y57: 4391.3825 | Z57: -0.075401072 | AA57: 6555.7237 | AB57: 0.11384666 | AC57: 3608.6926 | AD57: -0.001061875 | AE57: 4358.6433 | AF57: 0.024896834 | AG57: 6685.0861 | AH57: 0.043509704 | AI57: 3889.5941 | AJ57: 0.048501909 | AK57: 2185.1495 | AL57: 0.039515322 | AM57: 22368.286 | AN57: -0.0013766058 | AO57: 8838.1786 | AP57: 0.016202358 | AQ57: 6753.4561 | AR57: -0.016093847 | AS57: 5673.8729 | AT57: 0.0072566621 | AU57: 784.09706 | AV57: 0.1044486 | AW57: 2841.1953 | AX57: -0.12033885 | AY57: 422.49613 | AZ57: 0.00050795491 | BA57: 2430.5992 | BB57: -0.10146332 | BC57: 5329.7632 | BD57: -0.018988186 | BE57: -3100.5523 | BF57: 0.084692744
A58: 1991 | B58: 3 | C58: 112345.78 | D58: -0.013259338 | E58: 110228.26 | F58: -0.010234438 | G58: 1256.6457 | H58: 0.0042986442 | I58: 202.44965 | J58: -0.0051945342 | K58: 17246.917 | L58: 0.0092966335 | M58: 1428.6155 | N58: 0.065467934 | O58: 18688.797 | P58: -0.0015618635 | Q58: 3427.186 | R58: 0.030227257 | S58: 375.0574 | T58: 0.13296654 | U58: 9486.3651 | V58: -0.042338402 | W58: 13871.555 | X58: -0.10538913 | Y58: 4250.4705 | Z58: -0.06174716 | AA58: 6720.9483 | AB58: 0.13545481 | AC58: 4245.7997 | AD58: -0.0033273484 | AE58: 4382.9401 | AF58: 0.019727393 | AG58: 6651.5702 | AH58: 0.042576002 | AI58: 3753.0523 | AJ58: 0.035873216 | AK58: 2221.8959 | AL58: 0.044405489 | AM58: 22375.832 | AN58: -0.0067317313 | AO58: 8867.0614 | AP58: 0.0080868128 | AQ58: 6704.6644 | AR58: -0.032566597 | AS58: 5686.652 | AT58: 0.0090461114 | AU58: 792.96024 | AV58: 0.067582793 | AW58: 2805.2535 | AX58: -0.13018535 | AY58: 421.38784 | AZ58: -0.011850544 | BA58: 2333.3776 | BB58: -0.12446731 | BC58: 5265.4089 | BD58: -0.024607474 | BE58: -3153.6912 | BF58: 0.099054912
A59: 1991 | B59: 4 | C59: 115761.89 | D59: -0.0082370146 | E59: 113549.24 | F59: -0.0054466175 | G59: 1266.5496 | H59: 0.014587675 | I59: 193.66686 | J59: -0.057131935 | K59: 18238.984 | L59: -0.0025081449 | M59: 1457.5768 | N59: 0.072858644 | O59: 19908.074 | P59: -0.016332141 | Q59: 3581.8521 | R59: 0.036451226 | S59: 388.18395 | T59: 0.13693462 | U59: 8142.2314 | V59: -0.033087636 | W59: 17325.446 | X59: -0.058161659 | Y59: 5306.6632 | Z59: -0.023998166 | AA59: 6706.5454 | AB59: 0.11905957 | AC59: 3360.5092 | AD59: -0.010365889 | AE59: 4360.0178 | AF59: 0.0083541337 | AG59: 6613.2689 | AH59: 0.070575772 | AI59: 3590.4285 | AJ59: 0.082325139 | AK59: 2270.8579 | AL59: 0.057753594 | AM59: 22367.18 | AN59: -0.0059793979 | AO59: 8898.0605 | AP59: 0.0034671354 | AQ59: 6677.8412 | AR59: -0.034595936 | AS59: 5697.801 | AT59: 0.010349296 | AU59: 776.40958 | AV59: 0.0086131185 | AW59: 2731.2893 | AX59: -0.12390153 | AY59: 421.12326 | AZ59: -0.014252861 | BA59: 2431.3356 | BB59: -0.11078154 | BC59: 5340.466 | BD59: -0.026038299 | BE59: -3112.3094 | BF59: 0.080803955
